Workbook
Name Chat_lieu: OFFSET('Bảng giá giấy'!$B$3,MATCH('Bảng tính giá Tổng hợp'!A1&"*",Ma_Giay,0)-1,0,COUNTIF(Ma_Giay,'Bảng tính giá Tổng hợp'!A1&"*"),1)
Name Ma_Giay: OFFSET('Bảng giá giấy'!$B$3,0,0,COUNTA('Bảng giá giấy'!$B:$B)-2,1)

Sheet BG - Hộp Sóng Nắp Cài Pizza
A1: Bảng giá Hộp Sóng - Nắp Cài Pizza
D2: Đơn giá | AI2: Đơn giá
A3: Số lượng | B3: ='Bảng tính giá Tổng hợp'!C4 -> 10000 | D3: =L72/B3 -> 8392.8741 | F3: Kích thước | G3: Dài | H3: Rộng | I3: Cao | K3: Thành | L3: Tai cài | M3: Bù | N3: Nới xén | AF3: Số lượng | AG3: =IF('Bảng tính giá Tổng hợp'!L7="Không Khay",0,'Bảng tính giá Tổng hợp'!C4) -> 0 | AI3: =IFERROR(AQ72/AG3,0) -> 0 | AK3: Kích thước | AL3: Dài | AM3: Rộng | AN3: Cao | AP3: Bù xén Cao su/Foam
A4: Chất liệu | B4: ='Bảng tính giá Tổng hợp'!C9 -> i300 | G4: ='Bảng tính giá Tổng hợp'!B8 -> 32 | H4: ='Bảng tính giá Tổng hợp'!C8 -> 22 | I4: ='Bảng tính giá Tổng hợp'!D8 -> 8 | K4: ='Bảng tính giá Tổng hợp'!E8 -> 0.5 | M4: =IF(OR(B9="Không",B9=0),0.1,IF(AND(B9=""),0.1,0.1)) -> 0.1 | N4: =IF(OR(B9="Không",B9=0),0.2,IF(AND(B9=""),0.2,0.4)) -> 0.4 | AF4: Chất liệu | AG4: ='Bảng tính giá Tổng hợp'!M9 -> i300 | AL4: =G4-K4*2 -> 31 | AM4: =H4-N4 -> 21.6 | AN4: ='Bảng tính giá Tổng hợp'!N8 -> 4 | AP4: 0.4
A5: Cán | B5: ='Bảng tính giá Tổng hợp'!C10 -> Mờ | AF5: Cán | AG5: ='Bảng tính giá Tổng hợp'!M10 -> Mờ
A6: Số bát | B6: ='Bảng tính giá Tổng hợp'!C11 -> 1x1 | C6: =IF(B6="1x1",1*1,IF(B6="1x2",1*2,IF(B6="1x3",1*3,IF(B6="2x2",2*2,IF(B6="2x3",2*3,IF(B6="2x4",2*4,IF(B6="3x3",3*3,IF(B6="3x4",3*4,IF(B6="1x2 Ngang",1*2,IF(B6="1x3 Ngang",1*3,IF(B6="2x3 Ngang",2*3,IF(B6="2x4 Ngang",2*4,IF(B6="3x4 Ngang",3*4))))))))))))) -> 1 | F6: Định lượng giấy | G6: Bù hao | H6: Định lượng bồi | I6: Bù hao bồi | K6: Máy in | L6: Số màu | M6: Nội dung | N6: Cái/Thùng | AF6: Số bát | AG6: ='Bảng tính giá Tổng hợp'!M11 -> 1x2 | AH6: =IF(AG6="1x1",1*1,IF(AG6="1x2",1*2,IF(AG6="1x3",1*3,IF(AG6="2x2",2*2,IF(AG6="2x3",2*3,IF(AG6="2x4",2*4,IF(AG6="3x3",3*3,IF(AG6="3x4",3*4,IF(AG6="1x2 Ngang",1*2,IF(AG6="1x3 Ngang",1*3,IF(AG6="2x3 Ngang",2*3,IF(AG6="2x4 Ngang",2*4,IF(AG6="3x4 Ngang",3*4))))))))))))) -> 2 | AI6: Bù hao khay | AK6: Định lượng giấy | AL6: Bù hao | AM6: Định lượng bồi | AN6: Bù hao bồi | AP6: Máy in | AQ6: Số màu | AR6: Nội dung | AS6: Cái/Thùng
A7: Dây xách | B7: ='Bảng tính giá Tổng hợp'!C17 -> 0 | F7: =IFERROR(VLOOKUP(B4,'Bảng giá giấy'!$B:$C,2,0),0) -> 300 | G7: =IF(OR(B10="Bạc",B10="Bạc Prime",B10="Vàng",B10="Vàng Prime",B13="Có",B14="Có",B15="Có",B18="Có",B21="Bóng",B21="Cát"),IF(B3/C6*5%<150,150,B3/C6*5%),IF(B3/C6*4%<100,100,B3/C6*4%)) -> 400 | H7: =IFERROR(VLOOKUP(B9,'Bảng giá giấy'!$B:$C,2,0),0) -> 1 | I7: =IF(B3/C6*3%<100,100,B3/C6*3%) -> 300 | K7: =IF(B14="Có","UV",IF(OR($D$88+1>54.5,$E$88>79),16,IF(AND($D$88+1<=52.5,$E$88<=72.5),IF(L7=1,12,10),IF(L7=1,12,16)))) -> 16 | L7: ='Bảng tính giá Tổng hợp'!C12 -> 4 | M7: 1 | N7: 200 | AF7: Dây xách | AG7: 0 | AI7: 20 | AK7: =IFERROR(VLOOKUP(AG4,'Bảng giá giấy'!$B:$C,2,0),0) -> 300 | AL7: =IF(OR(AF10="Bạc",AF10="Bạc Prime",AF10="Vàng",AF10="Vàng Prime",AF13="Có",AF14="Có",AF15="Có",AF18="Có",AF21="Bóng",AF21="Cát"),IF(AG3/AH6*3%<150,150,AG3/AH6*3%),IF(AG3/AH6*2.5%<100,100,AG3/AH6*2.5%)) -> 100 | AM7: =IFERROR(VLOOKUP(AG9,'Bảng giá giấy'!$B:$C,2,0),0) -> 1 | AN7: =IF(AG3/AH6*2.5%<100,100,AG3/AH6*2.5%) -> 100 | AP7: =IF(AG14="Có","UV",IF(OR(AI88+1>54.5,AJ88>79),16,IF(AND(AI88+1<=52.5,AJ88<=72.5),IF(AP7=1,12,10),IF(AP7=1,12,16)))) -> 10 | AQ7: ='Bảng tính giá Tổng hợp'!M12 -> 1 | AR7: 1 | AS7: 1500
A8: Vận chuyển | B8: 0 | AF8: Vận chuyển | AG8: 0
A9: Bồi | B9: ='Bảng tính giá Tổng hợp'!C13 -> Sóng E Nâu | F9: Gia công | G9: Giá cán | H9: Giá in | I9: Giá lượt | J9: Giá giấy | K9: Giá Giấy Bồi | L9: Giá Bồi | N9: Giá Metalize | AF9: Bồi | AG9: ='Bảng tính giá Tổng hợp'!M13 -> Sóng E Nâu | AK9: Gia công | AL9: Giá cán | AM9: Giá in | AN9: Giá lượt | AO9: Giá giấy | AP9: Giá Giấy Bồi | AQ9: Giá Bồi | AS9: Giá Metalize
A10: Ghép Màng Metalize | B10: ='Bảng tính giá Tổng hợp'!C14 -> 0 | F10: =IF(OR(B9="Không",B9=0,B9=""),IF(B3<5000,250,200),IF(B3<5000,500,350)) -> 350 | G10: =IF(B5="mờ",0.22,IF(B5="bóng",0.2,IF(B5=0,0,IF(B5="Đặc biệt",1.2)))) -> 0.22 | H10: =IF(K7=8,90000,IF(K7=10,100000,IF(K7=12,170000,IF(K7=16,230000,IF(K7="UV",580000))))) -> 230000 | I10: =IF(K7=8,35,IF(K7=10,40,IF(K7=12,70,IF(K7=16,80,IF(K7="UV",180))))) -> 80 | J10: =IFERROR(VLOOKUP(B4,'Bảng giá giấy'!$B:$D,3,0),0) -> 17.4 | K10: =IFERROR(VLOOKUP(B9,'Bảng giá giấy'!$B:$D,3,0),0) -> 3800 | L10: 1300 | N10: =IF(B10="Bạc",0.31,IF(B10="Bạc Prime",0.37,IF(B10="Vàng",0.4,IF(B10="Vàng Prime",0.44)))) -> FALSE | AF10: Ghép Màng Metalize | AG10: ='Bảng tính giá Tổng hợp'!M14 -> 0 | AK10: =IF(OR(AG9="Không",AG9=0,AG9=""),IF(AG3<5000,200,150),IF(AG3<5000,500,350)) -> 500 | AL10: =IF(AG5="mờ",0.22,IF(AG5="bóng",0.2,IF(AG5=0,0,IF(AG5="Đặc biệt",1.2)))) -> 0.22 | AM10: =IF(AP7=8,90000,IF(AP7=10,100000,IF(AP7=12,170000,IF(AP7=16,230000,IF(AP7="UV",580000))))) -> 100000 | AN10: =IF(AP7=8,35,IF(AP7=10,40,IF(AP7=12,70,IF(AP7=16,80,IF(AP7="UV",180))))) -> 40 | AO10: =IFERROR(VLOOKUP(AG4,'Bảng giá giấy'!$B:$D,3,0),0) -> 17.4 | AP10: =IFERROR(VLOOKUP(AG9,'Bảng giá giấy'!$B:$D,3,0),0) -> 3800 | AQ10: 1300 | AS10: =IF(AG10="Bạc",0.31,IF(AG10="Bạc Prime",0.37,IF(AG10="Vàng",0.4,IF(AG10="Vàng Prime",0.44)))) -> FALSE
A11: In Mặt trong | B11: ='Bảng tính giá Tổng hợp'!C18 -> 0 | C11: Màu | H11: Giá in mặt trong | AF11: In Mặt trong | AG11: 0 | AH11: Màu | AM11: Giá in mặt trong
A12: Cán Mặt trong | B12: ='Bảng tính giá Tổng hợp'!C19 -> 0 | H12: =IF(K7=8,120000,IF(K7=10,150000,IF(K7=12,200000,IF(K7=16,250000,IF(K7="UV",250000))))) -> 250000 | I12: =IF(K7=8,40,IF(K7=10,50,IF(K7=12,70,IF(K7=16,100,IF(K7="UV",100))))) -> 100 | AF12: Cán Mặt trong | AG12: 0 | AM12: =IF(AP7=8,120000,IF(AP7=10,150000,IF(AP7=12,200000,IF(AP7=16,250000,IF(AP7="UV",250000))))) -> 150000 | AN12: =IF(AP7=8,40,IF(AP7=10,50,IF(AP7=12,70,IF(AP7=16,100,IF(AP7="UV",100))))) -> 50 | AS12: Thùng Cao Su
A13: Lăn Vân | B13: ='Bảng tính giá Tổng hợp'!C16 -> 0 | AF13: Lăn Vân | AG13: ='Bảng tính giá Tổng hợp'!M16 -> 0 | AS13: =IF(AF24+AF26=0,0,1000/(AF24+AF26)) -> 0
A14: In Offset UV | B14: ='Bảng tính giá Tổng hợp'!C15 -> 0 | G14: Dài | H14: Rộng | I14: Số vị trí | J14: Cm2 | AF14: In Offset UV | AG14: ='Bảng tính giá Tổng hợp'!M15 -> 0 | AL14: Dài | AM14: Rộng | AN14: Số vị trí | AO14: Cm2
A15: Ép nhũ 1 | B15: ='Bảng tính giá Tổng hợp'!C25 -> 0 | C15: ='Bảng tính giá Tổng hợp'!D25 -> 1 Mặt | F15: Kích thước | G15: ='Bảng tính giá Tổng hợp'!C26 -> 0 | H15: ='Bảng tính giá Tổng hợp'!D26 -> 0 | I15: ='Bảng tính giá Tổng hợp'!E26 -> 1 | J15: =IF(G15*H15<=100,100,G15*H15) -> 100 | AF15: Ép nhũ 1 | AG15: ='Bảng tính giá Tổng hợp'!M25 -> 0 | AH15: ='Bảng tính giá Tổng hợp'!N25 -> 1 Mặt | AK15: Kích thước | AL15: ='Bảng tính giá Tổng hợp'!M26 -> 0 | AM15: ='Bảng tính giá Tổng hợp'!N26 -> 0 | AN15: ='Bảng tính giá Tổng hợp'!O26 -> 1 | AO15: =IF(AL15*AM15<=100,100,AL15*AM15) -> 100
A16: Ép nhũ 2 | B16: ='Bảng tính giá Tổng hợp'!C27 -> 0 | C16: ='Bảng tính giá Tổng hợp'!D27 -> 1 Mặt | F16: Kích thước | G16: ='Bảng tính giá Tổng hợp'!C28 -> 0 | H16: ='Bảng tính giá Tổng hợp'!D28 -> 0 | I16: ='Bảng tính giá Tổng hợp'!E28 -> 1 | J16: =IF(G16*H16<=100,100,G16*H16) -> 100 | AF16: Ép nhũ 2 | AG16: ='Bảng tính giá Tổng hợp'!M27 -> 0 | AH16: ='Bảng tính giá Tổng hợp'!N27 -> 1 Mặt | AK16: Kích thước | AL16: ='Bảng tính giá Tổng hợp'!M28 -> 0 | AM16: ='Bảng tính giá Tổng hợp'!N28 -> 0 | AN16: ='Bảng tính giá Tổng hợp'!O28 -> 1 | AO16: =IF(AL16*AM16<=100,100,AL16*AM16) -> 100
A17: Ép nhũ 3 | B17: ='Bảng tính giá Tổng hợp'!C29 -> 0 | C17: ='Bảng tính giá Tổng hợp'!D29 -> 1 Mặt | F17: Kích thước | G17: ='Bảng tính giá Tổng hợp'!C30 -> 0 | H17: ='Bảng tính giá Tổng hợp'!D30 -> 0 | I17: ='Bảng tính giá Tổng hợp'!E30 -> 1 | J17: =IF(G17*H17<=100,100,G17*H17) -> 100 | AF17: Ép nhũ 3 | AG17: ='Bảng tính giá Tổng hợp'!M29 -> 0 | AH17: ='Bảng tính giá Tổng hợp'!N29 -> 1 Mặt | AK17: Kích thước | AL17: ='Bảng tính giá Tổng hợp'!M30 -> 0 | AM17: ='Bảng tính giá Tổng hợp'!N30 -> 0 | AN17: ='Bảng tính giá Tổng hợp'!O30 -> 1 | AO17: =IF(AL17*AM17<=100,100,AL17*AM17) -> 100
A18: Thúc nổi 1 | B18: ='Bảng tính giá Tổng hợp'!C31 -> 0 | C18: ='Bảng tính giá Tổng hợp'!D31 -> 1 Mặt | F18: Kích thước | G18: ='Bảng tính giá Tổng hợp'!C32 -> 0 | H18: ='Bảng tính giá Tổng hợp'!D32 -> 0 | I18: ='Bảng tính giá Tổng hợp'!E32 -> 1 | J18: =IF(G18*H18*2<=100,100,G18*H18*2) -> 100 | AF18: Thúc nổi 1 | AG18: ='Bảng tính giá Tổng hợp'!M31 -> 0 | AH18: ='Bảng tính giá Tổng hợp'!N31 -> 1 Mặt | AK18: Kích thước | AL18: ='Bảng tính giá Tổng hợp'!M32 -> 0 | AM18: ='Bảng tính giá Tổng hợp'!N32 -> 0 | AN18: ='Bảng tính giá Tổng hợp'!O32 -> 1 | AO18: =IF(AL18*AM18*2<=100,100,AL18*AM18*2) -> 100
A19: Thúc nổi 2 | B19: 0 | C19: 1 Mặt | F19: Kích thước | G19: 0 | H19: 0 | I19: 1 | J19: =IF(G19*H19*2<=100,100,G19*H19*2) -> 100 | AF19: Thúc nổi 2 | AG19: 0 | AH19: 1 Mặt | AK19: Kích thước | AL19: 0 | AM19: 0 | AN19: 1 | AO19: =IF(AL19*AM19*2<=100,100,AL19*AM19*2) -> 100
A20: Thúc nổi 3 | B20: 0 | C20: 1 Mặt | F20: Kích thước | G20: 0 | H20: 0 | I20: 1 | J20: =IF(G20*H20*2<=100,100,G20*H20*2) -> 100 | AF20: Thúc nổi 3 | AG20: 0 | AH20: 1 Mặt | AK20: Kích thước | AL20: 0 | AM20: 0 | AN20: 1 | AO20: =IF(AL20*AM20*2<=100,100,AL20*AM20*2) -> 100
A21: Lưới UV | B21: ='Bảng tính giá Tổng hợp'!C23 -> 0 | C21: 1 Mặt | AF21: Lưới UV | AG21: ='Bảng tính giá Tổng hợp'!M23 -> 0 | AH21: 1 Mặt
AF23: Cao su non
AF24: ='Bảng tính giá Tổng hợp'!M17 -> 0
AF25: Xốp Foam
AF26: ='Bảng tính giá Tổng hợp'!M18 -> 0
AF27: Bồi
AF28: ='Bảng tính giá Tổng hợp'!M19 -> 0
AM34: =AL4+AP4 -> 31.4 | AN34: =AM4+AP4 -> 22
AG35: Giá | AK35: Liền | AL35: Kt Carton Thân | AM35: =IF(AM34>AN34,AM34,AN34) -> 31.4 | AN35: =IF(AN34<AM34,AN34,AM34) -> 22
AM36: Dài | AN36: Rộng | AO36: Thừa | AR36: Số bát | AS36: SL Carton
AG37: 15000 | AH37: Xốp Foam | AI37: =IFERROR(AS37*AK37*AF26,0) -> 0 | AJ37: 1x1 | AK37: =AG37 -> 15000 | AM37: 100 | AN37: 100 | AP37: =ROUNDDOWN(AM37/AM35,0) -> 3 | AQ37: =ROUNDDOWN(AN37/AN35,0) -> 4 | AR37: =AP37*AQ37 -> 12 | AS37: =ROUNDUP((AG3+AI7)/(AR37+AR38),0) -> 2
AH38: Khổ thừa | AM38: =AM37-AP37*AM35 -> 5.8 | AN38: =AN37-AN35*AQ37 -> 12 | AO38: =IF(AP37*AM35<AN37,100,AN37-AN35*AQ37) -> 100 | AP38: =ROUNDDOWN(IF(AM38>AN38,AM38/AN35,AN38/AN35),0) -> 0 | AQ38: =ROUNDDOWN(IF(AM38>AN38,AL38/AM35,AO38/AM35),0) -> 3 | AR38: =AP38*AQ38 -> 0
AI39: =IFERROR(AS39*AK37*AF26,0) -> 0 | AJ39: 1x1 | AK39: =AG37 -> 15000 | AM39: 100 | AN39: 100 | AP39: =ROUNDDOWN(AM39/AN35,0) -> 4 | AQ39: =ROUNDDOWN(AN39/AM35,0) -> 3 | AR39: =AP39*AQ39 -> 12 | AS39: =ROUNDUP((AG3+AI7)/(AR39+AR40),0) -> 2
AH40: Khổ thừa | AM40: =AM39-AP39*AN35 -> 12 | AN40: =AN39-AQ39*AM35 -> 5.8 | AO40: =IF(AQ39*AM35<100,100,AM39-AP39*AN35) -> 100 | AP40: =ROUNDDOWN(IF(AM40>AN40,AM40/AN35,AN40/AN35),0) -> 0 | AQ40: =ROUNDDOWN(IF(AM40>AN40,AL40/AM35,AO40/AM35),0) -> 0 | AR40: =AP40*AQ40 -> 0
AH41: Rẻ nhất | AI41: {=MIN(IF(AI37:AI40<>0,AI37:AI40))} -> 0 | AJ41: =VLOOKUP(AI41,AI37:AS40,2,0) -> 1x1 | AS41: =VLOOKUP(AI41,AI37:AS40,11,0) -> 2
AG43: 120000 | AH43: Cao Su non | AI43: =IFERROR(AS43*AK43*AF24,0) -> 0 | AJ43: 1.22x2.44 | AK43: =AG43 -> 120000 | AM43: 240 | AN43: 121 | AP43: =ROUNDDOWN(AM43/AM35,0) -> 7 | AQ43: =ROUNDDOWN(AN43/AN35,0) -> 5 | AR43: =AP43*AQ43 -> 35 | AS43: =ROUNDUP((AG3+AI7)/(AR43+AR44),0) -> 1
AH44: Khổ thừa | AL44: 240 | AM44: =AM43-AM35*AP43 -> 20.2 | AN44: =AN43-AN35*AQ43 -> 11 | AO44: 121 | AP44: =ROUNDDOWN(IF(AM44>AN44,AM44/AN35,AN44/AN35),0) -> 0 | AQ44: =ROUNDDOWN(IF(AM44>AN44,AL44/AM35,AO44/AM35),0) -> 7 | AR44: =AP44*AQ44 -> 0
AI45: =IFERROR(AS45*AK45*AF24,0) -> 0 | AJ45: 1.22x2.44 | AK45: =AG43 -> 120000 | AM45: 121 | AN45: 240 | AP45: =ROUNDDOWN(AM45/AM35,0) -> 3 | AQ45: =ROUNDDOWN(AN45/AN35,0) -> 10 | AR45: =AP45*AQ45 -> 30 | AS45: =ROUNDUP((AG3+AI7)/(AR45+AR46),0) -> 1
AH46: Khổ thừa | AL46: 240 | AM46: =AM45-AM35*AP45 -> 26.8 | AN46: =AN45-AQ45*AN35 -> 20 | AO46: 121 | AP46: =ROUNDDOWN(IF(AM46>AN46,AM46/AN35,AN46/AN35),0) -> 1 | AQ46: =ROUNDDOWN(IF(AM46>AN46,AL46/AM35,AO46/AM35),0) -> 7 | AR46: =AP46*AQ46 -> 7
AH47: Rẻ nhất | AI47: {=MIN(IF(AI43:AI46<>0,AI43:AI46))} -> 0 | AJ47: =VLOOKUP(AI47,AI43:AS46,2,0) -> 1.22x2.44 | AS47: =VLOOKUP(AI47,AI43:AS46,11,0) -> 1
...

Sheet Bảng tính giá Tổng hợp
B2: Hộp Sóng - Nắp cài Pizza
B4: Số lượng | C4: 10000 | E4: 0.15 | G4: Giá thành | H4: ='BG - Hộp Sóng Nắp Cài Pizza'!D3+'BG - Hộp Sóng Nắp Cài Pizza'!AI3 -> 8392.8741
B6: NẮP | E6: ='BG - Hộp Sóng Nắp Cài Pizza'!D3 -> 8392.8741 | L6: KHAY ĐỊNH HÌNH | O6: ='BG - Hộp Sóng Nắp Cài Pizza'!AI3 -> 0
B7: Dài | C7: Rộng | D7: Cao | E7: Thành | L7: Không Khay | N7: Cao
B8: 32 | C8: 22 | D8: 8 | E8: 0.5 | N8: 4
B9: Chất liệu giấy | C9: i300 | L9: Chất liệu giấy | M9: i300
B10: Cán | C10: Mờ | L10: Cán | M10: Mờ
B11: Số bát/tờ in | C11: 1x1 | L11: Số bát/tờ in | M11: 1x2
B12: Số màu | C12: 4 | D12: 2m = 1 Pha | L12: Số màu | M12: 1 | N12: 2m = 1 Pha
B13: Bồi | C13: Sóng E Nâu | L13: Bồi | M13: Sóng E Nâu
B14: Ghép Metalize | C14: 0 | L14: Ghép Metalize | M14: 0
B15: In Offset UV | C15: 0 | L15: In Offset UV | M15: 0
B16: Lăn Vân | C16: 0 | L16: Lăn Vân | M16: 0
B17: Dây xách | C17: 0 | L17: Khay Cao Su non | M17: 0 | N17: cm
B18: In Mặt trong | C18: 0 | D18: Màu | L18: Khay Xốp Foam | M18: 0 | N18: cm
B19: Cán Mặt trong | C19: 0 | L19: Bồi | M19: 0
B20: Xả lô | C20: =IF('BG - Hộp Sóng Nắp Cài Pizza'!$D$88>'BG - Hộp Sóng Nắp Cài Pizza'!$E$88,'BG - Hộp Sóng Nắp Cài Pizza'!$E$88,'BG - Hộp Sóng Nắp Cài Pizza'!$D$88) -> 65.4 | D20: =IF('BG - Hộp Sóng Nắp Cài Pizza'!$E$88<'BG - Hộp Sóng Nắp Cài Pizza'!$D$88,'BG - Hộp Sóng Nắp Cài Pizza'!$D$88,'BG - Hộp Sóng Nắp Cài Pizza'!$E$88) -> 68.3 | E20: Số lượng | L20: Xả lô | M20: =IF('BG - Hộp Sóng Nắp Cài Pizza'!$AI$88>'BG - Hộp Sóng Nắp Cài Pizza'!$AJ$88,'BG - Hộp Sóng Nắp Cài Pizza'!$AJ$88,'BG - Hộp Sóng Nắp Cài Pizza'!$AI$88) -> 39 | N20: =IF('BG - Hộp Sóng Nắp Cài Pizza'!$AJ$88<'BG - Hộp Sóng Nắp Cài Pizza'!$AI$88,'BG - Hộp Sóng Nắp Cài Pizza'!$AI$88,'BG - Hộp Sóng Nắp Cài Pizza'!$AJ$88) -> 59.2 | O20: Số lượng
B21: Nhập Khổ chuẩn | C21: =IF(C20>D20,D20,C20) -> 65.4 | D21: =IF(C21=D20,C20,D20) -> 68.3 | E21: ='BG - Hộp Sóng Nắp Cài Pizza'!G89 -> 10400 | L21: Nhập Khổ chuẩn | M21: =IF(M20>N20,N20,M20) -> 39 | N21: =IF(M21=N20,M20,N20) -> 59.2 | O21: ='BG - Hộp Sóng Nắp Cài Pizza'!AL89 -> 100
B22: LƯU Ý | C22: Nhỏ hơn | D22: Lớn hơn | L22: LƯU Ý | M22: Nhỏ hơn | N22: Lớn hơn
B23: Lưới UV | C23: 0 | L23: Lưới UV | M23: 0
C24: Dài | D24: Rộng | E24: Số vị trí | M24: Dài | N24: Rộng | O24: Số vị trí
B25: Ép nhũ 1 | C25: 0 | D25: 1 Mặt | L25: Ép nhũ 1 | M25: 0 | N25: 1 Mặt
B26: Kích thước khuôn | C26: 0 | D26: 0 | E26: 1 | L26: Kích thước khuôn | M26: 0 | N26: 0 | O26: 1
B27: Ép nhũ 2 | C27: 0 | D27: 1 Mặt | L27: Ép nhũ 2 | M27: 0 | N27: 1 Mặt
B28: Kích thước khuôn | C28: 0 | D28: 0 | E28: 1 | L28: Kích thước khuôn | M28: 0 | N28: 0 | O28: 1
B29: Ép nhũ 3 | C29: 0 | D29: 1 Mặt | L29: Ép nhũ 3 | M29: 0 | N29: 1 Mặt
B30: Kích thước khuôn | C30: 0 | D30: 0 | E30: 1 | L30: Kích thước khuôn | M30: 0 | N30: 0 | O30: 1
B31: Thúc nổi | C31: 0 | D31: 1 Mặt | L31: Thúc nổi | M31: 0 | N31: 1 Mặt
B32: Kích thước khuôn | C32: 0 | D32: 0 | E32: 1 | L32: Kích thước khuôn | M32: 0 | N32: 0 | O32: 1

Sheet Bảng giá giấy
B1: Bảng giá Giấy
A2: Tên giấy | B2: Mã giấy | C2: Định lượng | D2: Giá
B3: C80 | C3: 80 | D3: 23.6
B4: C100 | C4: 100 | D4: 21.8
B5: C120 | C5: 120 | D5: =D4 -> 21.8
B6: C140 | C6: 140 | D6: =D4 -> 21.8
B7: C150 | C7: 150 | D7: =D4 -> 21.8
B8: C180 | C8: 180 | D8: =D4 -> 21.8
B9: C200 | C9: 200 | D9: =D4 -> 21.8
B10: C230 | C10: 230 | D10: =D4 -> 21.8
B11: C250 | C11: 250 | D11: =D4 -> 21.8
B12: C300 | C12: 300 | D12: =D4 -> 21.8
B13: C-P300 | C13: 300 | D13: 24.3
B14: C-P350 | C14: 350 | D14: =D13 -> 24.3
B15: Carton 1.5 | D15: 11350
B16: Carton 1.6 | D16: 11776
B17: Carton 1.8 | D17: 13552
B18: Carton 1.8 Trắng | D18: 16188
B19: Carton 2.0 | D19: 14729
B20: Carton 2.0 Trắng | D20: 16629
B21: Carton 2.2 | D21: 15905
B22: Carton 2.2 Trắng | D22: 19115
B23: Carton 2.4 | D23: 17945
B24: Carton 2.4 Trắng | D24: 19666
B25: Carton 2.8 | D25: 20913
B26: Carton 3.0 | D26: 21337
B27: I210 | C27: 210 | D27: 18.2
B28: I230 | C28: 230 | D28: 17.4
B29: I250 | C29: 250 | D29: =D28 -> 17.4
B30: I280 | C30: 280 | D30: =D28 -> 17.4
B31: I300 | C31: 300 | D31: =D28 -> 17.4
B32: I350 | C32: 350 | D32: =D28 -> 17.4
B33: I400 | C33: 400 | D33: =D28 -> 17.4
B34: D250 | C34: 250 | D34: 16.5
B35: D300 | C35: 300 | D35: 15.5
B36: D350 | C36: 350 | D36: 15.2
B37: D400 | C37: 400 | D37: =D36 -> 15.2
B38: Op70 | C38: 70 | D38: 22
B39: Op80 | C39: 80 | D39: =D38 -> 22
B40: Op100 | C40: 100 | D40: =D38 -> 22
...
